Workbook

Sheet Inputs
A2: Uniform value (optional): | D2: Buffer | Q2: Resin
A3: Buffer: | D3: =IF($B$3="","",$B$3) | E3: =IF($B$3="","",$B$3) | F3: =IF($B$3="","",$B$3) | G3: =IF($B$3="","",$B$3) | H3: =IF($B$3="","",$B$3) | I3: =IF($B$3="","",$B$3) | J3: =IF($B$3="","",$B$3) | K3: =IF($B$3="","",$B$3) | ... O3: =IF($B$3="","",$B$3) | Q3: =IF($B$11="","",$B$11) | R3: =IF($B$11="","",$B$11) | S3: =IF($B$11="","",$B$11) | T3: =IF($B$11="","",$B$11) | U3: =IF($B$11="","",$B$11) | V3: =IF($B$11="","",$B$11) | W3: =IF($B$11="","",$B$11) | X3: =IF($B$11="","",$B$11) | ... AB3: =IF($B$11="","",$B$11)
A4: pH: | D4: =IF($B$3="","",$B$3) | E4: =IF($B$3="","",$B$3) | F4: =IF($B$3="","",$B$3) | G4: =IF($B$3="","",$B$3) | H4: =IF($B$3="","",$B$3) | I4: =IF($B$3="","",$B$3) | J4: =IF($B$3="","",$B$3) | K4: =IF($B$3="","",$B$3) | ... O4: =IF($B$3="","",$B$3) | Q4: =IF($B$11="","",$B$11) | R4: =IF($B$11="","",$B$11) | S4: =IF($B$11="","",$B$11) | T4: =IF($B$11="","",$B$11) | U4: =IF($B$11="","",$B$11) | V4: =IF($B$11="","",$B$11) | W4: =IF($B$11="","",$B$11) | X4: =IF($B$11="","",$B$11) | ... AB4: =IF($B$11="","",$B$11)
A5: Buffer conc (mM): | D5: =IF($B$3="","",$B$3) | E5: =IF($B$3="","",$B$3) | F5: =IF($B$3="","",$B$3) | G5: =IF($B$3="","",$B$3) | H5: =IF($B$3="","",$B$3) | I5: =IF($B$3="","",$B$3) | J5: =IF($B$3="","",$B$3) | K5: =IF($B$3="","",$B$3) | ... O5: =IF($B$3="","",$B$3) | Q5: =IF($B$11="","",$B$11) | R5: =IF($B$11="","",$B$11) | S5: =IF($B$11="","",$B$11) | T5: =IF($B$11="","",$B$11) | U5: =IF($B$11="","",$B$11) | V5: =IF($B$11="","",$B$11) | W5: =IF($B$11="","",$B$11) | X5: =IF($B$11="","",$B$11) | ... AB5: =IF($B$11="","",$B$11)
D6: =IF($B$3="","",$B$3) | E6: =IF($B$3="","",$B$3) | F6: =IF($B$3="","",$B$3) | G6: =IF($B$3="","",$B$3) | H6: =IF($B$3="","",$B$3) | I6: =IF($B$3="","",$B$3) | J6: =IF($B$3="","",$B$3) | K6: =IF($B$3="","",$B$3) | ... O6: =IF($B$3="","",$B$3) | Q6: =IF($B$11="","",$B$11) | R6: =IF($B$11="","",$B$11) | S6: =IF($B$11="","",$B$11) | T6: =IF($B$11="","",$B$11) | U6: =IF($B$11="","",$B$11) | V6: =IF($B$11="","",$B$11) | W6: =IF($B$11="","",$B$11) | X6: =IF($B$11="","",$B$11) | ... AB6: =IF($B$11="","",$B$11)
A7: Salt: | D7: =IF($B$3="","",$B$3) | E7: =IF($B$3="","",$B$3) | F7: =IF($B$3="","",$B$3) | G7: =IF($B$3="","",$B$3) | H7: =IF($B$3="","",$B$3) | I7: =IF($B$3="","",$B$3) | J7: =IF($B$3="","",$B$3) | K7: =IF($B$3="","",$B$3) | ... O7: =IF($B$3="","",$B$3) | Q7: =IF($B$11="","",$B$11) | R7: =IF($B$11="","",$B$11) | S7: =IF($B$11="","",$B$11) | T7: =IF($B$11="","",$B$11) | U7: =IF($B$11="","",$B$11) | V7: =IF($B$11="","",$B$11) | W7: =IF($B$11="","",$B$11) | X7: =IF($B$11="","",$B$11) | ... AB7: =IF($B$11="","",$B$11)
A8: Salt/cond units: | D8: =IF($B$3="","",$B$3) | E8: =IF($B$3="","",$B$3) | F8: =IF($B$3="","",$B$3) | G8: =IF($B$3="","",$B$3) | H8: =IF($B$3="","",$B$3) | I8: =IF($B$3="","",$B$3) | J8: =IF($B$3="","",$B$3) | K8: =IF($B$3="","",$B$3) | ... O8: =IF($B$3="","",$B$3) | Q8: =IF($B$11="","",$B$11) | R8: =IF($B$11="","",$B$11) | S8: =IF($B$11="","",$B$11) | T8: =IF($B$11="","",$B$11) | U8: =IF($B$11="","",$B$11) | V8: =IF($B$11="","",$B$11) | W8: =IF($B$11="","",$B$11) | X8: =IF($B$11="","",$B$11) | ... AB8: =IF($B$11="","",$B$11)
A9: Salt/cond conc: | D9: =IF($B$3="","",$B$3) | E9: =IF($B$3="","",$B$3) | F9: =IF($B$3="","",$B$3) | G9: =IF($B$3="","",$B$3) | H9: =IF($B$3="","",$B$3) | I9: =IF($B$3="","",$B$3) | J9: =IF($B$3="","",$B$3) | K9: =IF($B$3="","",$B$3) | ... O9: =IF($B$3="","",$B$3) | Q9: =IF($B$11="","",$B$11) | R9: =IF($B$11="","",$B$11) | S9: =IF($B$11="","",$B$11) | T9: =IF($B$11="","",$B$11) | U9: =IF($B$11="","",$B$11) | V9: =IF($B$11="","",$B$11) | W9: =IF($B$11="","",$B$11) | X9: =IF($B$11="","",$B$11) | ... AB9: =IF($B$11="","",$B$11)
D10: =IF($B$3="","",$B$3) | E10: =IF($B$3="","",$B$3) | F10: =IF($B$3="","",$B$3) | G10: =IF($B$3="","",$B$3) | H10: =IF($B$3="","",$B$3) | I10: =IF($B$3="","",$B$3) | J10: =IF($B$3="","",$B$3) | K10: =IF($B$3="","",$B$3) | ... O10: =IF($B$3="","",$B$3) | Q10: =IF($B$11="","",$B$11) | R10: =IF($B$11="","",$B$11) | S10: =IF($B$11="","",$B$11) | T10: =IF($B$11="","",$B$11) | U10: =IF($B$11="","",$B$11) | V10: =IF($B$11="","",$B$11) | W10: =IF($B$11="","",$B$11) | X10: =IF($B$11="","",$B$11) | ... AB10: =IF($B$11="","",$B$11)
A11: Resin:
A12: Resin vol, Vres (µL): | D12: pH | Q12: Resin vol, Vres (µL)
D13: =IF($B$4="","",$B$4) | E13: =IF($B$4="","",$B$4) | F13: =IF($B$4="","",$B$4) | G13: =IF($B$4="","",$B$4) | H13: =IF($B$4="","",$B$4) | I13: =IF($B$4="","",$B$4) | J13: =IF($B$4="","",$B$4) | K13: =IF($B$4="","",$B$4) | ... O13: =IF($B$4="","",$B$4) | Q13: =IF($B$12="","",$B$12) | R13: =IF($B$12="","",$B$12) | S13: =IF($B$12="","",$B$12) | T13: =IF($B$12="","",$B$12) | U13: =IF($B$12="","",$B$12) | V13: =IF($B$12="","",$B$12) | W13: =IF($B$12="","",$B$12) | X13: =IF($B$12="","",$B$12) | ... AB13: =IF($B$12="","",$B$12)
A14: Load vol, Vliq (µL): | D14: =IF($B$4="","",$B$4) | E14: =IF($B$4="","",$B$4) | F14: =IF($B$4="","",$B$4) | G14: =IF($B$4="","",$B$4) | H14: =IF($B$4="","",$B$4) | I14: =IF($B$4="","",$B$4) | J14: =IF($B$4="","",$B$4) | K14: =IF($B$4="","",$B$4) | ... O14: =IF($B$4="","",$B$4) | Q14: =IF($B$12="","",$B$12) | R14: =IF($B$12="","",$B$12) | S14: =IF($B$12="","",$B$12) | T14: =IF($B$12="","",$B$12) | U14: =IF($B$12="","",$B$12) | V14: =IF($B$12="","",$B$12) | W14: =IF($B$12="","",$B$12) | X14: =IF($B$12="","",$B$12) | ... AB14: =IF($B$12="","",$B$12)
A15: Load conc, C0 (g/L): | D15: =IF($B$4="","",$B$4) | E15: =IF($B$4="","",$B$4) | F15: =IF($B$4="","",$B$4) | G15: =IF($B$4="","",$B$4) | H15: =IF($B$4="","",$B$4) | I15: =IF($B$4="","",$B$4) | J15: =IF($B$4="","",$B$4) | K15: =IF($B$4="","",$B$4) | ... O15: =IF($B$4="","",$B$4) | Q15: =IF($B$12="","",$B$12) | R15: =IF($B$12="","",$B$12) | S15: =IF($B$12="","",$B$12) | T15: =IF($B$12="","",$B$12) | U15: =IF($B$12="","",$B$12) | V15: =IF($B$12="","",$B$12) | W15: =IF($B$12="","",$B$12) | X15: =IF($B$12="","",$B$12) | ... AB15: =IF($B$12="","",$B$12)
D16: =IF($B$4="","",$B$4) | E16: =IF($B$4="","",$B$4) | F16: =IF($B$4="","",$B$4) | G16: =IF($B$4="","",$B$4) | H16: =IF($B$4="","",$B$4) | I16: =IF($B$4="","",$B$4) | J16: =IF($B$4="","",$B$4) | K16: =IF($B$4="","",$B$4) | ... O16: =IF($B$4="","",$B$4) | Q16: =IF($B$12="","",$B$12) | R16: =IF($B$12="","",$B$12) | S16: =IF($B$12="","",$B$12) | T16: =IF($B$12="","",$B$12) | U16: =IF($B$12="","",$B$12) | V16: =IF($B$12="","",$B$12) | W16: =IF($B$12="","",$B$12) | X16: =IF($B$12="","",$B$12) | ... AB16: =IF($B$12="","",$B$12)
A17: Holdup vol, Vholdup (µL): | D17: =IF($B$4="","",$B$4) | E17: =IF($B$4="","",$B$4) | F17: =IF($B$4="","",$B$4) | G17: =IF($B$4="","",$B$4) | H17: =IF($B$4="","",$B$4) | I17: =IF($B$4="","",$B$4) | J17: =IF($B$4="","",$B$4) | K17: =IF($B$4="","",$B$4) | ... O17: =IF($B$4="","",$B$4) | Q17: =IF($B$12="","",$B$12) | R17: =IF($B$12="","",$B$12) | S17: =IF($B$12="","",$B$12) | T17: =IF($B$12="","",$B$12) | U17: =IF($B$12="","",$B$12) | V17: =IF($B$12="","",$B$12) | W17: =IF($B$12="","",$B$12) | X17: =IF($B$12="","",$B$12) | ... AB17: =IF($B$12="","",$B$12)
D18: =IF($B$4="","",$B$4) | E18: =IF($B$4="","",$B$4) | F18: =IF($B$4="","",$B$4) | G18: =IF($B$4="","",$B$4) | H18: =IF($B$4="","",$B$4) | I18: =IF($B$4="","",$B$4) | J18: =IF($B$4="","",$B$4) | K18: =IF($B$4="","",$B$4) | ... O18: =IF($B$4="","",$B$4) | Q18: =IF($B$12="","",$B$12) | R18: =IF($B$12="","",$B$12) | S18: =IF($B$12="","",$B$12) | T18: =IF($B$12="","",$B$12) | U18: =IF($B$12="","",$B$12) | V18: =IF($B$12="","",$B$12) | W18: =IF($B$12="","",$B$12) | X18: =IF($B$12="","",$B$12) | ... AB18: =IF($B$12="","",$B$12)
D19: =IF($B$4="","",$B$4) | E19: =IF($B$4="","",$B$4) | F19: =IF($B$4="","",$B$4) | G19: =IF($B$4="","",$B$4) | H19: =IF($B$4="","",$B$4) | I19: =IF($B$4="","",$B$4) | J19: =IF($B$4="","",$B$4) | K19: =IF($B$4="","",$B$4) | ... O19: =IF($B$4="","",$B$4) | Q19: =IF($B$12="","",$B$12) | R19: =IF($B$12="","",$B$12) | S19: =IF($B$12="","",$B$12) | T19: =IF($B$12="","",$B$12) | U19: =IF($B$12="","",$B$12) | V19: =IF($B$12="","",$B$12) | W19: =IF($B$12="","",$B$12) | X19: =IF($B$12="","",$B$12) | ... AB19: =IF($B$12="","",$B$12)
A20: Color scheme: | D20: =IF($B$4="","",$B$4) | E20: =IF($B$4="","",$B$4) | F20: =IF($B$4="","",$B$4) | G20: =IF($B$4="","",$B$4) | H20: =IF($B$4="","",$B$4) | I20: =IF($B$4="","",$B$4) | J20: =IF($B$4="","",$B$4) | K20: =IF($B$4="","",$B$4) | ... O20: =IF($B$4="","",$B$4) | Q20: =IF($B$12="","",$B$12) | R20: =IF($B$12="","",$B$12) | S20: =IF($B$12="","",$B$12) | T20: =IF($B$12="","",$B$12) | U20: =IF($B$12="","",$B$12) | V20: =IF($B$12="","",$B$12) | W20: =IF($B$12="","",$B$12) | X20: =IF($B$12="","",$B$12) | ... AB20: =IF($B$12="","",$B$12)
A21: Empty
A22: Required entry | D22: Buffer conc (mM) | Q22: Load vol, Vliq (µL)
A23: Optional entry | D23: =IF($B$5="","",$B$5) | E23: =IF($B$5="","",$B$5) | F23: =IF($B$5="","",$B$5) | G23: =IF($B$5="","",$B$5) | H23: =IF($B$5="","",$B$5) | I23: =IF($B$5="","",$B$5) | J23: =IF($B$5="","",$B$5) | K23: =IF($B$5="","",$B$5) | ... O23: =IF($B$5="","",$B$5) | Q23: =IF($B$14="","",$B$14) | R23: =IF($B$14="","",$B$14) | S23: =IF($B$14="","",$B$14) | T23: =IF($B$14="","",$B$14) | U23: =IF($B$14="","",$B$14) | V23: =IF($B$14="","",$B$14) | W23: =IF($B$14="","",$B$14) | X23: =IF($B$14="","",$B$14) | ... AB23: =IF($B$14="","",$B$14)
A24: Formula (do not modify) | D24: =IF($B$5="","",$B$5) | E24: =IF($B$5="","",$B$5) | F24: =IF($B$5="","",$B$5) | G24: =IF($B$5="","",$B$5) | H24: =IF($B$5="","",$B$5) | I24: =IF($B$5="","",$B$5) | J24: =IF($B$5="","",$B$5) | K24: =IF($B$5="","",$B$5) | ... O24: =IF($B$5="","",$B$5) | Q24: =IF($B$14="","",$B$14) | R24: =IF($B$14="","",$B$14) | S24: =IF($B$14="","",$B$14) | T24: =IF($B$14="","",$B$14) | U24: =IF($B$14="","",$B$14) | V24: =IF($B$14="","",$B$14) | W24: =IF($B$14="","",$B$14) | X24: =IF($B$14="","",$B$14) | ... AB24: =IF($B$14="","",$B$14)
D25: =IF($B$5="","",$B$5) | E25: =IF($B$5="","",$B$5) | F25: =IF($B$5="","",$B$5) | G25: =IF($B$5="","",$B$5) | H25: =IF($B$5="","",$B$5) | I25: =IF($B$5="","",$B$5) | J25: =IF($B$5="","",$B$5) | K25: =IF($B$5="","",$B$5) | ... O25: =IF($B$5="","",$B$5) | Q25: =IF($B$14="","",$B$14) | R25: =IF($B$14="","",$B$14) | S25: =IF($B$14="","",$B$14) | T25: =IF($B$14="","",$B$14) | U25: =IF($B$14="","",$B$14) | V25: =IF($B$14="","",$B$14) | W25: =IF($B$14="","",$B$14) | X25: =IF($B$14="","",$B$14) | ... AB25: =IF($B$14="","",$B$14)
D26: =IF($B$5="","",$B$5) | E26: =IF($B$5="","",$B$5) | F26: =IF($B$5="","",$B$5) | G26: =IF($B$5="","",$B$5) | H26: =IF($B$5="","",$B$5) | I26: =IF($B$5="","",$B$5) | J26: =IF($B$5="","",$B$5) | K26: =IF($B$5="","",$B$5) | ... O26: =IF($B$5="","",$B$5) | Q26: =IF($B$14="","",$B$14) | R26: =IF($B$14="","",$B$14) | S26: =IF($B$14="","",$B$14) | T26: =IF($B$14="","",$B$14) | U26: =IF($B$14="","",$B$14) | V26: =IF($B$14="","",$B$14) | W26: =IF($B$14="","",$B$14) | X26: =IF($B$14="","",$B$14) | ... AB26: =IF($B$14="","",$B$14)
D27: =IF($B$5="","",$B$5) | E27: =IF($B$5="","",$B$5) | F27: =IF($B$5="","",$B$5) | G27: =IF($B$5="","",$B$5) | H27: =IF($B$5="","",$B$5) | I27: =IF($B$5="","",$B$5) | J27: =IF($B$5="","",$B$5) | K27: =IF($B$5="","",$B$5) | ... O27: =IF($B$5="","",$B$5) | Q27: =IF($B$14="","",$B$14) | R27: =IF($B$14="","",$B$14) | S27: =IF($B$14="","",$B$14) | T27: =IF($B$14="","",$B$14) | U27: =IF($B$14="","",$B$14) | V27: =IF($B$14="","",$B$14) | W27: =IF($B$14="","",$B$14) | X27: =IF($B$14="","",$B$14) | ... AB27: =IF($B$14="","",$B$14)
D28: =IF($B$5="","",$B$5) | E28: =IF($B$5="","",$B$5) | F28: =IF($B$5="","",$B$5) | G28: =IF($B$5="","",$B$5) | H28: =IF($B$5="","",$B$5) | I28: =IF($B$5="","",$B$5) | J28: =IF($B$5="","",$B$5) | K28: =IF($B$5="","",$B$5) | ... O28: =IF($B$5="","",$B$5) | Q28: =IF($B$14="","",$B$14) | R28: =IF($B$14="","",$B$14) | S28: =IF($B$14="","",$B$14) | T28: =IF($B$14="","",$B$14) | U28: =IF($B$14="","",$B$14) | V28: =IF($B$14="","",$B$14) | W28: =IF($B$14="","",$B$14) | X28: =IF($B$14="","",$B$14) | ... AB28: =IF($B$14="","",$B$14)
D29: =IF($B$5="","",$B$5) | E29: =IF($B$5="","",$B$5) | F29: =IF($B$5="","",$B$5) | G29: =IF($B$5="","",$B$5) | H29: =IF($B$5="","",$B$5) | I29: =IF($B$5="","",$B$5) | J29: =IF($B$5="","",$B$5) | K29: =IF($B$5="","",$B$5) | ... O29: =IF($B$5="","",$B$5) | Q29: =IF($B$14="","",$B$14) | R29: =IF($B$14="","",$B$14) | S29: =IF($B$14="","",$B$14) | T29: =IF($B$14="","",$B$14) | U29: =IF($B$14="","",$B$14) | V29: =IF($B$14="","",$B$14) | W29: =IF($B$14="","",$B$14) | X29: =IF($B$14="","",$B$14) | ... AB29: =IF($B$14="","",$B$14)
D30: =IF($B$5="","",$B$5) | E30: =IF($B$5="","",$B$5) | F30: =IF($B$5="","",$B$5) | G30: =IF($B$5="","",$B$5) | H30: =IF($B$5="","",$B$5) | I30: =IF($B$5="","",$B$5) | J30: =IF($B$5="","",$B$5) | K30: =IF($B$5="","",$B$5) | ... O30: =IF($B$5="","",$B$5) | Q30: =IF($B$14="","",$B$14) | R30: =IF($B$14="","",$B$14) | S30: =IF($B$14="","",$B$14) | T30: =IF($B$14="","",$B$14) | U30: =IF($B$14="","",$B$14) | V30: =IF($B$14="","",$B$14) | W30: =IF($B$14="","",$B$14) | X30: =IF($B$14="","",$B$14) | ... AB30: =IF($B$14="","",$B$14)
D32: Salt | Q32: Load conc, C0 (g/L)
D33: =IF($B$7="","",$B$7) | E33: =IF($B$7="","",$B$7) | F33: =IF($B$7="","",$B$7) | G33: =IF($B$7="","",$B$7) | H33: =IF($B$7="","",$B$7) | I33: =IF($B$7="","",$B$7) | J33: =IF($B$7="","",$B$7) | K33: =IF($B$7="","",$B$7) | ... O33: =IF($B$7="","",$B$7) | Q33: =IF($B$15="","",$B$15) | R33: =IF($B$15="","",$B$15) | S33: =IF($B$15="","",$B$15) | T33: =IF($B$15="","",$B$15) | U33: =IF($B$15="","",$B$15) | V33: =IF($B$15="","",$B$15) | W33: =IF($B$15="","",$B$15) | X33: =IF($B$15="","",$B$15) | ... AB33: =IF($B$15="","",$B$15)
D34: =IF($B$7="","",$B$7) | E34: =IF($B$7="","",$B$7) | F34: =IF($B$7="","",$B$7) | G34: =IF($B$7="","",$B$7) | H34: =IF($B$7="","",$B$7) | I34: =IF($B$7="","",$B$7) | J34: =IF($B$7="","",$B$7) | K34: =IF($B$7="","",$B$7) | ... O34: =IF($B$7="","",$B$7) | Q34: =IF($B$15="","",$B$15) | R34: =IF($B$15="","",$B$15) | S34: =IF($B$15="","",$B$15) | T34: =IF($B$15="","",$B$15) | U34: =IF($B$15="","",$B$15) | V34: =IF($B$15="","",$B$15) | W34: =IF($B$15="","",$B$15) | X34: =IF($B$15="","",$B$15) | ... AB34: =IF($B$15="","",$B$15)
D35: =IF($B$7="","",$B$7) | E35: =IF($B$7="","",$B$7) | F35: =IF($B$7="","",$B$7) | G35: =IF($B$7="","",$B$7) | H35: =IF($B$7="","",$B$7) | I35: =IF($B$7="","",$B$7) | J35: =IF($B$7="","",$B$7) | K35: =IF($B$7="","",$B$7) | ... O35: =IF($B$7="","",$B$7) | Q35: =IF($B$15="","",$B$15) | R35: =IF($B$15="","",$B$15) | S35: =IF($B$15="","",$B$15) | T35: =IF($B$15="","",$B$15) | U35: =IF($B$15="","",$B$15) | V35: =IF($B$15="","",$B$15) | W35: =IF($B$15="","",$B$15) | X35: =IF($B$15="","",$B$15) | ... AB35: =IF($B$15="","",$B$15)
D36: =IF($B$7="","",$B$7) | E36: =IF($B$7="","",$B$7) | F36: =IF($B$7="","",$B$7) | G36: =IF($B$7="","",$B$7) | H36: =IF($B$7="","",$B$7) | I36: =IF($B$7="","",$B$7) | J36: =IF($B$7="","",$B$7) | K36: =IF($B$7="","",$B$7) | ... O36: =IF($B$7="","",$B$7) | Q36: =IF($B$15="","",$B$15) | R36: =IF($B$15="","",$B$15) | S36: =IF($B$15="","",$B$15) | T36: =IF($B$15="","",$B$15) | U36: =IF($B$15="","",$B$15) | V36: =IF($B$15="","",$B$15) | W36: =IF($B$15="","",$B$15) | X36: =IF($B$15="","",$B$15) | ... AB36: =IF($B$15="","",$B$15)
D37: =IF($B$7="","",$B$7) | E37: =IF($B$7="","",$B$7) | F37: =IF($B$7="","",$B$7) | G37: =IF($B$7="","",$B$7) | H37: =IF($B$7="","",$B$7) | I37: =IF($B$7="","",$B$7) | J37: =IF($B$7="","",$B$7) | K37: =IF($B$7="","",$B$7) | ... O37: =IF($B$7="","",$B$7) | Q37: =IF($B$15="","",$B$15) | R37: =IF($B$15="","",$B$15) | S37: =IF($B$15="","",$B$15) | T37: =IF($B$15="","",$B$15) | U37: =IF($B$15="","",$B$15) | V37: =IF($B$15="","",$B$15) | W37: =IF($B$15="","",$B$15) | X37: =IF($B$15="","",$B$15) | ... AB37: =IF($B$15="","",$B$15)
D38: =IF($B$7="","",$B$7) | E38: =IF($B$7="","",$B$7) | F38: =IF($B$7="","",$B$7) | G38: =IF($B$7="","",$B$7) | H38: =IF($B$7="","",$B$7) | I38: =IF($B$7="","",$B$7) | J38: =IF($B$7="","",$B$7) | K38: =IF($B$7="","",$B$7) | ... O38: =IF($B$7="","",$B$7) | Q38: =IF($B$15="","",$B$15) | R38: =IF($B$15="","",$B$15) | S38: =IF($B$15="","",$B$15) | T38: =IF($B$15="","",$B$15) | U38: =IF($B$15="","",$B$15) | V38: =IF($B$15="","",$B$15) | W38: =IF($B$15="","",$B$15) | X38: =IF($B$15="","",$B$15) | ... AB38: =IF($B$15="","",$B$15)
D39: =IF($B$7="","",$B$7) | E39: =IF($B$7="","",$B$7) | F39: =IF($B$7="","",$B$7) | G39: =IF($B$7="","",$B$7) | H39: =IF($B$7="","",$B$7) | I39: =IF($B$7="","",$B$7) | J39: =IF($B$7="","",$B$7) | K39: =IF($B$7="","",$B$7) | ... O39: =IF($B$7="","",$B$7) | Q39: =IF($B$15="","",$B$15) | R39: =IF($B$15="","",$B$15) | S39: =IF($B$15="","",$B$15) | T39: =IF($B$15="","",$B$15) | U39: =IF($B$15="","",$B$15) | V39: =IF($B$15="","",$B$15) | W39: =IF($B$15="","",$B$15) | X39: =IF($B$15="","",$B$15) | ... AB39: =IF($B$15="","",$B$15)
D40: =IF($B$7="","",$B$7) | E40: =IF($B$7="","",$B$7) | F40: =IF($B$7="","",$B$7) | G40: =IF($B$7="","",$B$7) | H40: =IF($B$7="","",$B$7) | I40: =IF($B$7="","",$B$7) | J40: =IF($B$7="","",$B$7) | K40: =IF($B$7="","",$B$7) | ... O40: =IF($B$7="","",$B$7) | Q40: =IF($B$15="","",$B$15) | R40: =IF($B$15="","",$B$15) | S40: =IF($B$15="","",$B$15) | T40: =IF($B$15="","",$B$15) | U40: =IF($B$15="","",$B$15) | V40: =IF($B$15="","",$B$15) | W40: =IF($B$15="","",$B$15) | X40: =IF($B$15="","",$B$15) | ... AB40: =IF($B$15="","",$B$15)
D42: Salt/cond | F42: Units: | G42: =IF(B8="","",B8) | Q42: Holdup vol, Vholdup (µL)
D43: =IF($B$9="","",$B$9) | E43: =IF($B$9="","",$B$9) | F43: =IF($B$9="","",$B$9) | G43: =IF($B$9="","",$B$9) | H43: =IF($B$9="","",$B$9) | I43: =IF($B$9="","",$B$9) | J43: =IF($B$9="","",$B$9) | K43: =IF($B$9="","",$B$9) | ... O43: =IF($B$9="","",$B$9) | Q43: =IF($B$17="","",$B$17) | R43: =IF($B$17="","",$B$17) | S43: =IF($B$17="","",$B$17) | T43: =IF($B$17="","",$B$17) | U43: =IF($B$17="","",$B$17) | V43: =IF($B$17="","",$B$17) | W43: =IF($B$17="","",$B$17) | X43: =IF($B$17="","",$B$17) | ... AB43: =IF($B$17="","",$B$17)
...

Sheet UV calibration and raw data
B2: A280 | F2: A320 | J2: A280 - A320 | M2: Average | N2: StDev | P2: Stock conc (mg/mL) | AO2: A990 | AS2: A900 | AW2: A990 - A900 | AZ2: Average | BA2: StDev | BC2: Standard vol (µL)
J3: =IF(B3="","",B3-F3) | K3: =IF(C3="","",C3-G3) | L3: =IF(D3="","",D3-H3) | M3: =IF(J3="","",AVERAGE(J3:L3)) | N3: =IF(J3="","",STDEV(J3:L3)) | AW3: =IF(AO3="","",AO3-AS3) | AX3: =IF(AP3="","",AP3-AT3) | AY3: =IF(AQ3="","",AQ3-AU3) | AZ3: =IF(AW3="","",AVERAGE(AW3:AY3)) | BA3: =IF(AW3="","",STDEV(AW3:AY3))
J4: =IF(B4="","",B4-F4) | K4: =IF(C4="","",C4-G4) | L4: =IF(D4="","",D4-H4) | M4: =IF(J4="","",AVERAGE(J4:L4)) | N4: =IF(J4="","",STDEV(J4:L4)) | AW4: =IF(AO4="","",AO4-AS4) | AX4: =IF(AP4="","",AP4-AT4) | AY4: =IF(AQ4="","",AQ4-AU4) | AZ4: =IF(AW4="","",AVERAGE(AW4:AY4)) | BA4: =IF(AW4="","",STDEV(AW4:AY4))
J5: =IF(B5="","",B5-F5) | K5: =IF(C5="","",C5-G5) | L5: =IF(D5="","",D5-H5) | M5: =IF(J5="","",AVERAGE(J5:L5)) | N5: =IF(J5="","",STDEV(J5:L5)) | AW5: =IF(AO5="","",AO5-AS5) | AX5: =IF(AP5="","",AP5-AT5) | AY5: =IF(AQ5="","",AQ5-AU5) | AZ5: =IF(AW5="","",AVERAGE(AW5:AY5)) | BA5: =IF(AW5="","",STDEV(AW5:AY5))
J6: =IF(B6="","",B6-F6) | K6: =IF(C6="","",C6-G6) | L6: =IF(D6="","",D6-H6) | M6: =IF(J6="","",AVERAGE(J6:L6)) | N6: =IF(J6="","",STDEV(J6:L6)) | AW6: =IF(AO6="","",AO6-AS6) | AX6: =IF(AP6="","",AP6-AT6) | AY6: =IF(AQ6="","",AQ6-AU6) | AZ6: =IF(AW6="","",AVERAGE(AW6:AY6)) | BA6: =IF(AW6="","",STDEV(AW6:AY6))
J7: =IF(B7="","",B7-F7) | K7: =IF(C7="","",C7-G7) | L7: =IF(D7="","",D7-H7) | M7: =IF(J7="","",AVERAGE(J7:L7)) | N7: =IF(J7="","",STDEV(J7:L7)) | AW7: =IF(AO7="","",AO7-AS7) | AX7: =IF(AP7="","",AP7-AT7) | AY7: =IF(AQ7="","",AQ7-AU7) | AZ7: =IF(AW7="","",AVERAGE(AW7:AY7)) | BA7: =IF(AW7="","",STDEV(AW7:AY7))
J8: =IF(B8="","",B8-F8) | K8: =IF(C8="","",C8-G8) | L8: =IF(D8="","",D8-H8) | M8: =IF(J8="","",AVERAGE(J8:L8)) | N8: =IF(J8="","",STDEV(J8:L8)) | AW8: =IF(AO8="","",AO8-AS8) | AX8: =IF(AP8="","",AP8-AT8) | AY8: =IF(AQ8="","",AQ8-AU8) | AZ8: =IF(AW8="","",AVERAGE(AW8:AY8)) | BA8: =IF(AW8="","",STDEV(AW8:AY8))
J9: =IF(B9="","",B9-F9) | K9: =IF(C9="","",C9-G9) | L9: =IF(D9="","",D9-H9) | M9: =IF(J9="","",AVERAGE(J9:L9)) | N9: =IF(J9="","",STDEV(J9:L9)) | AW9: =IF(AO9="","",AO9-AS9) | AX9: =IF(AP9="","",AP9-AT9) | AY9: =IF(AQ9="","",AQ9-AU9) | AZ9: =IF(AW9="","",AVERAGE(AW9:AY9)) | BA9: =IF(AW9="","",STDEV(AW9:AY9))
J10: =IF(B10="","",B10-F10) | K10: =IF(C10="","",C10-G10) | L10: =IF(D10="","",D10-H10) | M10: =IF(J10="","",AVERAGE(J10:L10)) | N10: =IF(J10="","",STDEV(J10:L10)) | AW10: =IF(AO10="","",AO10-AS10) | AX10: =IF(AP10="","",AP10-AT10) | AY10: =IF(AQ10="","",AQ10-AU10) | AZ10: =IF(AW10="","",AVERAGE(AW10:AY10)) | BA10: =IF(AW10="","",STDEV(AW10:AY10))
B18: A280 calibration | AO18: Pathlength calibration
B19: y = mx + b | AO19: y = mx + b
B20: m | AO20: m
B21: b | AO21: b
B23: Load flowthrough | O23: Load plate initial (optional) | AB23: Strip flowthrough (optional) | AO23: Load flowthrough
B24: A280 | O24: A280 | AB24: A280 | AO24: A990
B34: A320 | O34: A320 | AB34: A320 | AO34: A900
B44: A280 - A320 | O44: A280 - A320 | AB44: A280 - A320 | AO44: A990 - A900
B45: =IF(B25="","",B25-B35) | C45: =IF(C25="","",C25-C35) | D45: =IF(D25="","",D25-D35) | E45: =IF(E25="","",E25-E35) | F45: =IF(F25="","",F25-F35) | G45: =IF(G25="","",G25-G35) | H45: =IF(H25="","",H25-H35) | I45: =IF(I25="","",I25-I35) | ... M45: =IF(M25="","",M25-M35) | O45: =IF(O25="","",O25-O35) | P45: =IF(P25="","",P25-P35) | Q45: =IF(Q25="","",Q25-Q35) | R45: =IF(R25="","",R25-R35) | S45: =IF(S25="","",S25-S35) | T45: =IF(T25="","",T25-T35) | U45: =IF(U25="","",U25-U35) | V45: =IF(V25="","",V25-V35) | ... Z45: =IF(Z25="","",Z25-Z35) | AB45: =IF(AB25="","",AB25-AB35) | AC45: =IF(AC25="","",AC25-AC35) | AD45: =IF(AD25="","",AD25-AD35) | AE45: =IF(AE25="","",AE25-AE35) | AF45: =IF(AF25="","",AF25-AF35) | AG45: =IF(AG25="","",AG25-AG35) | AH45: =IF(AH25="","",AH25-AH35) | AI45: =IF(AI25="","",AI25-AI35) | ... AM45: =IF(AM25="","",AM25-AM35) | AO45: =IF(AO25="","",IF(AO35="","",AO25-AO35)) | AP45: =IF(AP25="","",IF(AP35="","",AP25-AP35)) | AQ45: =IF(AQ25="","",IF(AQ35="","",AQ25-AQ35)) | AR45: =IF(AR25="","",IF(AR35="","",AR25-AR35)) | AS45: =IF(AS25="","",IF(AS35="","",AS25-AS35)) | AT45: =IF(AT25="","",IF(AT35="","",AT25-AT35)) | AU45: =IF(AU25="","",IF(AU35="","",AU25-AU35)) | AV45: =IF(AV25="","",IF(AV35="","",AV25-AV35)) | ... AZ45: =IF(AZ25="","",IF(AZ35="","",AZ25-AZ35))
B46: =IF(B26="","",B26-B36) | C46: =IF(C26="","",C26-C36) | D46: =IF(D26="","",D26-D36) | E46: =IF(E26="","",E26-E36) | F46: =IF(F26="","",F26-F36) | G46: =IF(G26="","",G26-G36) | H46: =IF(H26="","",H26-H36) | I46: =IF(I26="","",I26-I36) | ... M46: =IF(M26="","",M26-M36) | O46: =IF(O26="","",O26-O36) | P46: =IF(P26="","",P26-P36) | Q46: =IF(Q26="","",Q26-Q36) | R46: =IF(R26="","",R26-R36) | S46: =IF(S26="","",S26-S36) | T46: =IF(T26="","",T26-T36) | U46: =IF(U26="","",U26-U36) | V46: =IF(V26="","",V26-V36) | ... Z46: =IF(Z26="","",Z26-Z36) | AB46: =IF(AB26="","",AB26-AB36) | AC46: =IF(AC26="","",AC26-AC36) | AD46: =IF(AD26="","",AD26-AD36) | AE46: =IF(AE26="","",AE26-AE36) | AF46: =IF(AF26="","",AF26-AF36) | AG46: =IF(AG26="","",AG26-AG36) | AH46: =IF(AH26="","",AH26-AH36) | AI46: =IF(AI26="","",AI26-AI36) | ... AM46: =IF(AM26="","",AM26-AM36) | AO46: =IF(AO26="","",IF(AO36="","",AO26-AO36)) | AP46: =IF(AP26="","",IF(AP36="","",AP26-AP36)) | AQ46: =IF(AQ26="","",IF(AQ36="","",AQ26-AQ36)) | AR46: =IF(AR26="","",IF(AR36="","",AR26-AR36)) | AS46: =IF(AS26="","",IF(AS36="","",AS26-AS36)) | AT46: =IF(AT26="","",IF(AT36="","",AT26-AT36)) | AU46: =IF(AU26="","",IF(AU36="","",AU26-AU36)) | AV46: =IF(AV26="","",IF(AV36="","",AV26-AV36)) | ... AZ46: =IF(AZ26="","",IF(AZ36="","",AZ26-AZ36))
B47: =IF(B27="","",B27-B37) | C47: =IF(C27="","",C27-C37) | D47: =IF(D27="","",D27-D37) | E47: =IF(E27="","",E27-E37) | F47: =IF(F27="","",F27-F37) | G47: =IF(G27="","",G27-G37) | H47: =IF(H27="","",H27-H37) | I47: =IF(I27="","",I27-I37) | ... M47: =IF(M27="","",M27-M37) | O47: =IF(O27="","",O27-O37) | P47: =IF(P27="","",P27-P37) | Q47: =IF(Q27="","",Q27-Q37) | R47: =IF(R27="","",R27-R37) | S47: =IF(S27="","",S27-S37) | T47: =IF(T27="","",T27-T37) | U47: =IF(U27="","",U27-U37) | V47: =IF(V27="","",V27-V37) | ... Z47: =IF(Z27="","",Z27-Z37) | AB47: =IF(AB27="","",AB27-AB37) | AC47: =IF(AC27="","",AC27-AC37) | AD47: =IF(AD27="","",AD27-AD37) | AE47: =IF(AE27="","",AE27-AE37) | AF47: =IF(AF27="","",AF27-AF37) | AG47: =IF(AG27="","",AG27-AG37) | AH47: =IF(AH27="","",AH27-AH37) | AI47: =IF(AI27="","",AI27-AI37) | ... AM47: =IF(AM27="","",AM27-AM37) | AO47: =IF(AO27="","",IF(AO37="","",AO27-AO37)) | AP47: =IF(AP27="","",IF(AP37="","",AP27-AP37)) | AQ47: =IF(AQ27="","",IF(AQ37="","",AQ27-AQ37)) | AR47: =IF(AR27="","",IF(AR37="","",AR27-AR37)) | AS47: =IF(AS27="","",IF(AS37="","",AS27-AS37)) | AT47: =IF(AT27="","",IF(AT37="","",AT27-AT37)) | AU47: =IF(AU27="","",IF(AU37="","",AU27-AU37)) | AV47: =IF(AV27="","",IF(AV37="","",AV27-AV37)) | ... AZ47: =IF(AZ27="","",IF(AZ37="","",AZ27-AZ37))
B48: =IF(B28="","",B28-B38) | C48: =IF(C28="","",C28-C38) | D48: =IF(D28="","",D28-D38) | E48: =IF(E28="","",E28-E38) | F48: =IF(F28="","",F28-F38) | G48: =IF(G28="","",G28-G38) | H48: =IF(H28="","",H28-H38) | I48: =IF(I28="","",I28-I38) | ... M48: =IF(M28="","",M28-M38) | O48: =IF(O28="","",O28-O38) | P48: =IF(P28="","",P28-P38) | Q48: =IF(Q28="","",Q28-Q38) | R48: =IF(R28="","",R28-R38) | S48: =IF(S28="","",S28-S38) | T48: =IF(T28="","",T28-T38) | U48: =IF(U28="","",U28-U38) | V48: =IF(V28="","",V28-V38) | ... Z48: =IF(Z28="","",Z28-Z38) | AB48: =IF(AB28="","",AB28-AB38) | AC48: =IF(AC28="","",AC28-AC38) | AD48: =IF(AD28="","",AD28-AD38) | AE48: =IF(AE28="","",AE28-AE38) | AF48: =IF(AF28="","",AF28-AF38) | AG48: =IF(AG28="","",AG28-AG38) | AH48: =IF(AH28="","",AH28-AH38) | AI48: =IF(AI28="","",AI28-AI38) | ... AM48: =IF(AM28="","",AM28-AM38) | AO48: =IF(AO28="","",IF(AO38="","",AO28-AO38)) | AP48: =IF(AP28="","",IF(AP38="","",AP28-AP38)) | AQ48: =IF(AQ28="","",IF(AQ38="","",AQ28-AQ38)) | AR48: =IF(AR28="","",IF(AR38="","",AR28-AR38)) | AS48: =IF(AS28="","",IF(AS38="","",AS28-AS38)) | AT48: =IF(AT28="","",IF(AT38="","",AT28-AT38)) | AU48: =IF(AU28="","",IF(AU38="","",AU28-AU38)) | AV48: =IF(AV28="","",IF(AV38="","",AV28-AV38)) | ... AZ48: =IF(AZ28="","",IF(AZ38="","",AZ28-AZ38))
B49: =IF(B29="","",B29-B39) | C49: =IF(C29="","",C29-C39) | D49: =IF(D29="","",D29-D39) | E49: =IF(E29="","",E29-E39) | F49: =IF(F29="","",F29-F39) | G49: =IF(G29="","",G29-G39) | H49: =IF(H29="","",H29-H39) | I49: =IF(I29="","",I29-I39) | ... M49: =IF(M29="","",M29-M39) | O49: =IF(O29="","",O29-O39) | P49: =IF(P29="","",P29-P39) | Q49: =IF(Q29="","",Q29-Q39) | R49: =IF(R29="","",R29-R39) | S49: =IF(S29="","",S29-S39) | T49: =IF(T29="","",T29-T39) | U49: =IF(U29="","",U29-U39) | V49: =IF(V29="","",V29-V39) | ... Z49: =IF(Z29="","",Z29-Z39) | AB49: =IF(AB29="","",AB29-AB39) | AC49: =IF(AC29="","",AC29-AC39) | AD49: =IF(AD29="","",AD29-AD39) | AE49: =IF(AE29="","",AE29-AE39) | AF49: =IF(AF29="","",AF29-AF39) | AG49: =IF(AG29="","",AG29-AG39) | AH49: =IF(AH29="","",AH29-AH39) | AI49: =IF(AI29="","",AI29-AI39) | ... AM49: =IF(AM29="","",AM29-AM39) | AO49: =IF(AO29="","",IF(AO39="","",AO29-AO39)) | AP49: =IF(AP29="","",IF(AP39="","",AP29-AP39)) | AQ49: =IF(AQ29="","",IF(AQ39="","",AQ29-AQ39)) | AR49: =IF(AR29="","",IF(AR39="","",AR29-AR39)) | AS49: =IF(AS29="","",IF(AS39="","",AS29-AS39)) | AT49: =IF(AT29="","",IF(AT39="","",AT29-AT39)) | AU49: =IF(AU29="","",IF(AU39="","",AU29-AU39)) | AV49: =IF(AV29="","",IF(AV39="","",AV29-AV39)) | ... AZ49: =IF(AZ29="","",IF(AZ39="","",AZ29-AZ39))
B50: =IF(B30="","",B30-B40) | C50: =IF(C30="","",C30-C40) | D50: =IF(D30="","",D30-D40) | E50: =IF(E30="","",E30-E40) | F50: =IF(F30="","",F30-F40) | G50: =IF(G30="","",G30-G40) | H50: =IF(H30="","",H30-H40) | I50: =IF(I30="","",I30-I40) | ... M50: =IF(M30="","",M30-M40) | O50: =IF(O30="","",O30-O40) | P50: =IF(P30="","",P30-P40) | Q50: =IF(Q30="","",Q30-Q40) | R50: =IF(R30="","",R30-R40) | S50: =IF(S30="","",S30-S40) | T50: =IF(T30="","",T30-T40) | U50: =IF(U30="","",U30-U40) | V50: =IF(V30="","",V30-V40) | ... Z50: =IF(Z30="","",Z30-Z40) | AB50: =IF(AB30="","",AB30-AB40) | AC50: =IF(AC30="","",AC30-AC40) | AD50: =IF(AD30="","",AD30-AD40) | AE50: =IF(AE30="","",AE30-AE40) | AF50: =IF(AF30="","",AF30-AF40) | AG50: =IF(AG30="","",AG30-AG40) | AH50: =IF(AH30="","",AH30-AH40) | AI50: =IF(AI30="","",AI30-AI40) | ... AM50: =IF(AM30="","",AM30-AM40) | AO50: =IF(AO30="","",IF(AO40="","",AO30-AO40)) | AP50: =IF(AP30="","",IF(AP40="","",AP30-AP40)) | AQ50: =IF(AQ30="","",IF(AQ40="","",AQ30-AQ40)) | AR50: =IF(AR30="","",IF(AR40="","",AR30-AR40)) | AS50: =IF(AS30="","",IF(AS40="","",AS30-AS40)) | AT50: =IF(AT30="","",IF(AT40="","",AT30-AT40)) | AU50: =IF(AU30="","",IF(AU40="","",AU30-AU40)) | AV50: =IF(AV30="","",IF(AV40="","",AV30-AV40)) | ... AZ50: =IF(AZ30="","",IF(AZ40="","",AZ30-AZ40))
B51: =IF(B31="","",B31-B41) | C51: =IF(C31="","",C31-C41) | D51: =IF(D31="","",D31-D41) | E51: =IF(E31="","",E31-E41) | F51: =IF(F31="","",F31-F41) | G51: =IF(G31="","",G31-G41) | H51: =IF(H31="","",H31-H41) | I51: =IF(I31="","",I31-I41) | ... M51: =IF(M31="","",M31-M41) | O51: =IF(O31="","",O31-O41) | P51: =IF(P31="","",P31-P41) | Q51: =IF(Q31="","",Q31-Q41) | R51: =IF(R31="","",R31-R41) | S51: =IF(S31="","",S31-S41) | T51: =IF(T31="","",T31-T41) | U51: =IF(U31="","",U31-U41) | V51: =IF(V31="","",V31-V41) | ... Z51: =IF(Z31="","",Z31-Z41) | AB51: =IF(AB31="","",AB31-AB41) | AC51: =IF(AC31="","",AC31-AC41) | AD51: =IF(AD31="","",AD31-AD41) | AE51: =IF(AE31="","",AE31-AE41) | AF51: =IF(AF31="","",AF31-AF41) | AG51: =IF(AG31="","",AG31-AG41) | AH51: =IF(AH31="","",AH31-AH41) | AI51: =IF(AI31="","",AI31-AI41) | ... AM51: =IF(AM31="","",AM31-AM41) | AO51: =IF(AO31="","",IF(AO41="","",AO31-AO41)) | AP51: =IF(AP31="","",IF(AP41="","",AP31-AP41)) | AQ51: =IF(AQ31="","",IF(AQ41="","",AQ31-AQ41)) | AR51: =IF(AR31="","",IF(AR41="","",AR31-AR41)) | AS51: =IF(AS31="","",IF(AS41="","",AS31-AS41)) | AT51: =IF(AT31="","",IF(AT41="","",AT31-AT41)) | AU51: =IF(AU31="","",IF(AU41="","",AU31-AU41)) | AV51: =IF(AV31="","",IF(AV41="","",AV31-AV41)) | ... AZ51: =IF(AZ31="","",IF(AZ41="","",AZ31-AZ41))
B52: =IF(B32="","",B32-B42) | C52: =IF(C32="","",C32-C42) | D52: =IF(D32="","",D32-D42) | E52: =IF(E32="","",E32-E42) | F52: =IF(F32="","",F32-F42) | G52: =IF(G32="","",G32-G42) | H52: =IF(H32="","",H32-H42) | I52: =IF(I32="","",I32-I42) | ... M52: =IF(M32="","",M32-M42) | O52: =IF(O32="","",O32-O42) | P52: =IF(P32="","",P32-P42) | Q52: =IF(Q32="","",Q32-Q42) | R52: =IF(R32="","",R32-R42) | S52: =IF(S32="","",S32-S42) | T52: =IF(T32="","",T32-T42) | U52: =IF(U32="","",U32-U42) | V52: =IF(V32="","",V32-V42) | ... Z52: =IF(Z32="","",Z32-Z42) | AB52: =IF(AB32="","",AB32-AB42) | AC52: =IF(AC32="","",AC32-AC42) | AD52: =IF(AD32="","",AD32-AD42) | AE52: =IF(AE32="","",AE32-AE42) | AF52: =IF(AF32="","",AF32-AF42) | AG52: =IF(AG32="","",AG32-AG42) | AH52: =IF(AH32="","",AH32-AH42) | AI52: =IF(AI32="","",AI32-AI42) | ... AM52: =IF(AM32="","",AM32-AM42) | AO52: =IF(AO32="","",IF(AO42="","",AO32-AO42)) | AP52: =IF(AP32="","",IF(AP42="","",AP32-AP42)) | AQ52: =IF(AQ32="","",IF(AQ42="","",AQ32-AQ42)) | AR52: =IF(AR32="","",IF(AR42="","",AR32-AR42)) | AS52: =IF(AS32="","",IF(AS42="","",AS32-AS42)) | AT52: =IF(AT32="","",IF(AT42="","",AT32-AT42)) | AU52: =IF(AU32="","",IF(AU42="","",AU32-AU42)) | AV52: =IF(AV32="","",IF(AV42="","",AV32-AV42)) | ... AZ52: =IF(AZ32="","",IF(AZ42="","",AZ32-AZ42))
B54: Conc, C (mg/mL) | D54: Measured max: | F54: =IF(SUM(B55:M62)=0,"",MAX(B55:M62)) | O54: Conc, C0 (mg/mL) | Q54: Measured average: | S54: =IF(SUM(O55:Z62)=0,"",AVERAGE(O55:Z62)) | AB54: Conc (mg/mL | AO54: Corrected vol (µL)
B55: =IF(B45="","",B45*$C$20+$C$21) | C55: =IF(C45="","",C45*$C$20+$C$21) | D55: =IF(D45="","",D45*$C$20+$C$21) | E55: =IF(E45="","",E45*$C$20+$C$21) | F55: =IF(F45="","",F45*$C$20+$C$21) | G55: =IF(G45="","",G45*$C$20+$C$21) | H55: =IF(H45="","",H45*$C$20+$C$21) | I55: =IF(I45="","",I45*$C$20+$C$21) | ... M55: =IF(M45="","",M45*$C$20+$C$21) | O55: =IF(O45="","",O45*$C$20+$C$21) | P55: =IF(P45="","",P45*$C$20+$C$21) | Q55: =IF(Q45="","",Q45*$C$20+$C$21) | R55: =IF(R45="","",R45*$C$20+$C$21) | S55: =IF(S45="","",S45*$C$20+$C$21) | T55: =IF(T45="","",T45*$C$20+$C$21) | U55: =IF(U45="","",U45*$C$20+$C$21) | V55: =IF(V45="","",V45*$C$20+$C$21) | ... Z55: =IF(Z45="","",Z45*$C$20+$C$21) | AB55: =IF(AB45="","",AB45*$C$20+$C$21) | AC55: =IF(AC45="","",AC45*$C$20+$C$21) | AD55: =IF(AD45="","",AD45*$C$20+$C$21) | AE55: =IF(AE45="","",AE45*$C$20+$C$21) | AF55: =IF(AF45="","",AF45*$C$20+$C$21) | AG55: =IF(AG45="","",AG45*$C$20+$C$21) | AH55: =IF(AH45="","",AH45*$C$20+$C$21) | AI55: =IF(AI45="","",AI45*$C$20+$C$21) | ... AM55: =IF(AM45="","",AM45*$C$20+$C$21) | AO55: =IF(AO45="","",AO45*$AP$20+$AP$21) | AP55: =IF(AP45="","",AP45*$AP$20+$AP$21) | AQ55: =IF(AQ45="","",AQ45*$AP$20+$AP$21) | AR55: =IF(AR45="","",AR45*$AP$20+$AP$21) | AS55: =IF(AS45="","",AS45*$AP$20+$AP$21) | AT55: =IF(AT45="","",AT45*$AP$20+$AP$21) | AU55: =IF(AU45="","",AU45*$AP$20+$AP$21) | AV55: =IF(AV45="","",AV45*$AP$20+$AP$21) | ... AZ55: =IF(AZ45="","",AZ45*$AP$20+$AP$21)
B56: =IF(B46="","",B46*$C$20+$C$21) | C56: =IF(C46="","",C46*$C$20+$C$21) | D56: =IF(D46="","",D46*$C$20+$C$21) | E56: =IF(E46="","",E46*$C$20+$C$21) | F56: =IF(F46="","",F46*$C$20+$C$21) | G56: =IF(G46="","",G46*$C$20+$C$21) | H56: =IF(H46="","",H46*$C$20+$C$21) | I56: =IF(I46="","",I46*$C$20+$C$21) | ... M56: =IF(M46="","",M46*$C$20+$C$21) | O56: =IF(O46="","",O46*$C$20+$C$21) | P56: =IF(P46="","",P46*$C$20+$C$21) | Q56: =IF(Q46="","",Q46*$C$20+$C$21) | R56: =IF(R46="","",R46*$C$20+$C$21) | S56: =IF(S46="","",S46*$C$20+$C$21) | T56: =IF(T46="","",T46*$C$20+$C$21) | U56: =IF(U46="","",U46*$C$20+$C$21) | V56: =IF(V46="","",V46*$C$20+$C$21) | ... Z56: =IF(Z46="","",Z46*$C$20+$C$21) | AB56: =IF(AB46="","",AB46*$C$20+$C$21) | AC56: =IF(AC46="","",AC46*$C$20+$C$21) | AD56: =IF(AD46="","",AD46*$C$20+$C$21) | AE56: =IF(AE46="","",AE46*$C$20+$C$21) | AF56: =IF(AF46="","",AF46*$C$20+$C$21) | AG56: =IF(AG46="","",AG46*$C$20+$C$21) | AH56: =IF(AH46="","",AH46*$C$20+$C$21) | AI56: =IF(AI46="","",AI46*$C$20+$C$21) | ... AM56: =IF(AM46="","",AM46*$C$20+$C$21) | AO56: =IF(AO46="","",AO46*$AP$20+$AP$21) | AP56: =IF(AP46="","",AP46*$AP$20+$AP$21) | AQ56: =IF(AQ46="","",AQ46*$AP$20+$AP$21) | AR56: =IF(AR46="","",AR46*$AP$20+$AP$21) | AS56: =IF(AS46="","",AS46*$AP$20+$AP$21) | AT56: =IF(AT46="","",AT46*$AP$20+$AP$21) | AU56: =IF(AU46="","",AU46*$AP$20+$AP$21) | AV56: =IF(AV46="","",AV46*$AP$20+$AP$21) | ... AZ56: =IF(AZ46="","",AZ46*$AP$20+$AP$21)
B57: =IF(B47="","",B47*$C$20+$C$21) | C57: =IF(C47="","",C47*$C$20+$C$21) | D57: =IF(D47="","",D47*$C$20+$C$21) | E57: =IF(E47="","",E47*$C$20+$C$21) | F57: =IF(F47="","",F47*$C$20+$C$21) | G57: =IF(G47="","",G47*$C$20+$C$21) | H57: =IF(H47="","",H47*$C$20+$C$21) | I57: =IF(I47="","",I47*$C$20+$C$21) | ... M57: =IF(M47="","",M47*$C$20+$C$21) | O57: =IF(O47="","",O47*$C$20+$C$21) | P57: =IF(P47="","",P47*$C$20+$C$21) | Q57: =IF(Q47="","",Q47*$C$20+$C$21) | R57: =IF(R47="","",R47*$C$20+$C$21) | S57: =IF(S47="","",S47*$C$20+$C$21) | T57: =IF(T47="","",T47*$C$20+$C$21) | U57: =IF(U47="","",U47*$C$20+$C$21) | V57: =IF(V47="","",V47*$C$20+$C$21) | ... Z57: =IF(Z47="","",Z47*$C$20+$C$21) | AB57: =IF(AB47="","",AB47*$C$20+$C$21) | AC57: =IF(AC47="","",AC47*$C$20+$C$21) | AD57: =IF(AD47="","",AD47*$C$20+$C$21) | AE57: =IF(AE47="","",AE47*$C$20+$C$21) | AF57: =IF(AF47="","",AF47*$C$20+$C$21) | AG57: =IF(AG47="","",AG47*$C$20+$C$21) | AH57: =IF(AH47="","",AH47*$C$20+$C$21) | AI57: =IF(AI47="","",AI47*$C$20+$C$21) | ... AM57: =IF(AM47="","",AM47*$C$20+$C$21) | AO57: =IF(AO47="","",AO47*$AP$20+$AP$21) | AP57: =IF(AP47="","",AP47*$AP$20+$AP$21) | AQ57: =IF(AQ47="","",AQ47*$AP$20+$AP$21) | AR57: =IF(AR47="","",AR47*$AP$20+$AP$21) | AS57: =IF(AS47="","",AS47*$AP$20+$AP$21) | AT57: =IF(AT47="","",AT47*$AP$20+$AP$21) | AU57: =IF(AU47="","",AU47*$AP$20+$AP$21) | AV57: =IF(AV47="","",AV47*$AP$20+$AP$21) | ... AZ57: =IF(AZ47="","",AZ47*$AP$20+$AP$21)
B58: =IF(B48="","",B48*$C$20+$C$21) | C58: =IF(C48="","",C48*$C$20+$C$21) | D58: =IF(D48="","",D48*$C$20+$C$21) | E58: =IF(E48="","",E48*$C$20+$C$21) | F58: =IF(F48="","",F48*$C$20+$C$21) | G58: =IF(G48="","",G48*$C$20+$C$21) | H58: =IF(H48="","",H48*$C$20+$C$21) | I58: =IF(I48="","",I48*$C$20+$C$21) | ... M58: =IF(M48="","",M48*$C$20+$C$21) | O58: =IF(O48="","",O48*$C$20+$C$21) | P58: =IF(P48="","",P48*$C$20+$C$21) | Q58: =IF(Q48="","",Q48*$C$20+$C$21) | R58: =IF(R48="","",R48*$C$20+$C$21) | S58: =IF(S48="","",S48*$C$20+$C$21) | T58: =IF(T48="","",T48*$C$20+$C$21) | U58: =IF(U48="","",U48*$C$20+$C$21) | V58: =IF(V48="","",V48*$C$20+$C$21) | ... Z58: =IF(Z48="","",Z48*$C$20+$C$21) | AB58: =IF(AB48="","",AB48*$C$20+$C$21) | AC58: =IF(AC48="","",AC48*$C$20+$C$21) | AD58: =IF(AD48="","",AD48*$C$20+$C$21) | AE58: =IF(AE48="","",AE48*$C$20+$C$21) | AF58: =IF(AF48="","",AF48*$C$20+$C$21) | AG58: =IF(AG48="","",AG48*$C$20+$C$21) | AH58: =IF(AH48="","",AH48*$C$20+$C$21) | AI58: =IF(AI48="","",AI48*$C$20+$C$21) | ... AM58: =IF(AM48="","",AM48*$C$20+$C$21) | AO58: =IF(AO48="","",AO48*$AP$20+$AP$21) | AP58: =IF(AP48="","",AP48*$AP$20+$AP$21) | AQ58: =IF(AQ48="","",AQ48*$AP$20+$AP$21) | AR58: =IF(AR48="","",AR48*$AP$20+$AP$21) | AS58: =IF(AS48="","",AS48*$AP$20+$AP$21) | AT58: =IF(AT48="","",AT48*$AP$20+$AP$21) | AU58: =IF(AU48="","",AU48*$AP$20+$AP$21) | AV58: =IF(AV48="","",AV48*$AP$20+$AP$21) | ... AZ58: =IF(AZ48="","",AZ48*$AP$20+$AP$21)
B59: =IF(B49="","",B49*$C$20+$C$21) | C59: =IF(C49="","",C49*$C$20+$C$21) | D59: =IF(D49="","",D49*$C$20+$C$21) | E59: =IF(E49="","",E49*$C$20+$C$21) | F59: =IF(F49="","",F49*$C$20+$C$21) | G59: =IF(G49="","",G49*$C$20+$C$21) | H59: =IF(H49="","",H49*$C$20+$C$21) | I59: =IF(I49="","",I49*$C$20+$C$21) | ... M59: =IF(M49="","",M49*$C$20+$C$21) | O59: =IF(O49="","",O49*$C$20+$C$21) | P59: =IF(P49="","",P49*$C$20+$C$21) | Q59: =IF(Q49="","",Q49*$C$20+$C$21) | R59: =IF(R49="","",R49*$C$20+$C$21) | S59: =IF(S49="","",S49*$C$20+$C$21) | T59: =IF(T49="","",T49*$C$20+$C$21) | U59: =IF(U49="","",U49*$C$20+$C$21) | V59: =IF(V49="","",V49*$C$20+$C$21) | ... Z59: =IF(Z49="","",Z49*$C$20+$C$21) | AB59: =IF(AB49="","",AB49*$C$20+$C$21) | AC59: =IF(AC49="","",AC49*$C$20+$C$21) | AD59: =IF(AD49="","",AD49*$C$20+$C$21) | AE59: =IF(AE49="","",AE49*$C$20+$C$21) | AF59: =IF(AF49="","",AF49*$C$20+$C$21) | AG59: =IF(AG49="","",AG49*$C$20+$C$21) | AH59: =IF(AH49="","",AH49*$C$20+$C$21) | AI59: =IF(AI49="","",AI49*$C$20+$C$21) | ... AM59: =IF(AM49="","",AM49*$C$20+$C$21) | AO59: =IF(AO49="","",AO49*$AP$20+$AP$21) | AP59: =IF(AP49="","",AP49*$AP$20+$AP$21) | AQ59: =IF(AQ49="","",AQ49*$AP$20+$AP$21) | AR59: =IF(AR49="","",AR49*$AP$20+$AP$21) | AS59: =IF(AS49="","",AS49*$AP$20+$AP$21) | AT59: =IF(AT49="","",AT49*$AP$20+$AP$21) | AU59: =IF(AU49="","",AU49*$AP$20+$AP$21) | AV59: =IF(AV49="","",AV49*$AP$20+$AP$21) | ... AZ59: =IF(AZ49="","",AZ49*$AP$20+$AP$21)
B60: =IF(B50="","",B50*$C$20+$C$21) | C60: =IF(C50="","",C50*$C$20+$C$21) | D60: =IF(D50="","",D50*$C$20+$C$21) | E60: =IF(E50="","",E50*$C$20+$C$21) | F60: =IF(F50="","",F50*$C$20+$C$21) | G60: =IF(G50="","",G50*$C$20+$C$21) | H60: =IF(H50="","",H50*$C$20+$C$21) | I60: =IF(I50="","",I50*$C$20+$C$21) | ... M60: =IF(M50="","",M50*$C$20+$C$21) | O60: =IF(O50="","",O50*$C$20+$C$21) | P60: =IF(P50="","",P50*$C$20+$C$21) | Q60: =IF(Q50="","",Q50*$C$20+$C$21) | R60: =IF(R50="","",R50*$C$20+$C$21) | S60: =IF(S50="","",S50*$C$20+$C$21) | T60: =IF(T50="","",T50*$C$20+$C$21) | U60: =IF(U50="","",U50*$C$20+$C$21) | V60: =IF(V50="","",V50*$C$20+$C$21) | ... Z60: =IF(Z50="","",Z50*$C$20+$C$21) | AB60: =IF(AB50="","",AB50*$C$20+$C$21) | AC60: =IF(AC50="","",AC50*$C$20+$C$21) | AD60: =IF(AD50="","",AD50*$C$20+$C$21) | AE60: =IF(AE50="","",AE50*$C$20+$C$21) | AF60: =IF(AF50="","",AF50*$C$20+$C$21) | AG60: =IF(AG50="","",AG50*$C$20+$C$21) | AH60: =IF(AH50="","",AH50*$C$20+$C$21) | AI60: =IF(AI50="","",AI50*$C$20+$C$21) | ... AM60: =IF(AM50="","",AM50*$C$20+$C$21) | AO60: =IF(AO50="","",AO50*$AP$20+$AP$21) | AP60: =IF(AP50="","",AP50*$AP$20+$AP$21) | AQ60: =IF(AQ50="","",AQ50*$AP$20+$AP$21) | AR60: =IF(AR50="","",AR50*$AP$20+$AP$21) | AS60: =IF(AS50="","",AS50*$AP$20+$AP$21) | AT60: =IF(AT50="","",AT50*$AP$20+$AP$21) | AU60: =IF(AU50="","",AU50*$AP$20+$AP$21) | AV60: =IF(AV50="","",AV50*$AP$20+$AP$21) | ... AZ60: =IF(AZ50="","",AZ50*$AP$20+$AP$21)
B61: =IF(B51="","",B51*$C$20+$C$21) | C61: =IF(C51="","",C51*$C$20+$C$21) | D61: =IF(D51="","",D51*$C$20+$C$21) | E61: =IF(E51="","",E51*$C$20+$C$21) | F61: =IF(F51="","",F51*$C$20+$C$21) | G61: =IF(G51="","",G51*$C$20+$C$21) | H61: =IF(H51="","",H51*$C$20+$C$21) | I61: =IF(I51="","",I51*$C$20+$C$21) | ... M61: =IF(M51="","",M51*$C$20+$C$21) | O61: =IF(O51="","",O51*$C$20+$C$21) | P61: =IF(P51="","",P51*$C$20+$C$21) | Q61: =IF(Q51="","",Q51*$C$20+$C$21) | R61: =IF(R51="","",R51*$C$20+$C$21) | S61: =IF(S51="","",S51*$C$20+$C$21) | T61: =IF(T51="","",T51*$C$20+$C$21) | U61: =IF(U51="","",U51*$C$20+$C$21) | V61: =IF(V51="","",V51*$C$20+$C$21) | ... Z61: =IF(Z51="","",Z51*$C$20+$C$21) | AB61: =IF(AB51="","",AB51*$C$20+$C$21) | AC61: =IF(AC51="","",AC51*$C$20+$C$21) | AD61: =IF(AD51="","",AD51*$C$20+$C$21) | AE61: =IF(AE51="","",AE51*$C$20+$C$21) | AF61: =IF(AF51="","",AF51*$C$20+$C$21) | AG61: =IF(AG51="","",AG51*$C$20+$C$21) | AH61: =IF(AH51="","",AH51*$C$20+$C$21) | AI61: =IF(AI51="","",AI51*$C$20+$C$21) | ... AM61: =IF(AM51="","",AM51*$C$20+$C$21) | AO61: =IF(AO51="","",AO51*$AP$20+$AP$21) | AP61: =IF(AP51="","",AP51*$AP$20+$AP$21) | AQ61: =IF(AQ51="","",AQ51*$AP$20+$AP$21) | AR61: =IF(AR51="","",AR51*$AP$20+$AP$21) | AS61: =IF(AS51="","",AS51*$AP$20+$AP$21) | AT61: =IF(AT51="","",AT51*$AP$20+$AP$21) | AU61: =IF(AU51="","",AU51*$AP$20+$AP$21) | AV61: =IF(AV51="","",AV51*$AP$20+$AP$21) | ... AZ61: =IF(AZ51="","",AZ51*$AP$20+$AP$21)
B62: =IF(B52="","",B52*$C$20+$C$21) | C62: =IF(C52="","",C52*$C$20+$C$21) | D62: =IF(D52="","",D52*$C$20+$C$21) | E62: =IF(E52="","",E52*$C$20+$C$21) | F62: =IF(F52="","",F52*$C$20+$C$21) | G62: =IF(G52="","",G52*$C$20+$C$21) | H62: =IF(H52="","",H52*$C$20+$C$21) | I62: =IF(I52="","",I52*$C$20+$C$21) | ... M62: =IF(M52="","",M52*$C$20+$C$21) | O62: =IF(O52="","",O52*$C$20+$C$21) | P62: =IF(P52="","",P52*$C$20+$C$21) | Q62: =IF(Q52="","",Q52*$C$20+$C$21) | R62: =IF(R52="","",R52*$C$20+$C$21) | S62: =IF(S52="","",S52*$C$20+$C$21) | T62: =IF(T52="","",T52*$C$20+$C$21) | U62: =IF(U52="","",U52*$C$20+$C$21) | V62: =IF(V52="","",V52*$C$20+$C$21) | ... Z62: =IF(Z52="","",Z52*$C$20+$C$21) | AB62: =IF(AB52="","",AB52*$C$20+$C$21) | AC62: =IF(AC52="","",AC52*$C$20+$C$21) | AD62: =IF(AD52="","",AD52*$C$20+$C$21) | AE62: =IF(AE52="","",AE52*$C$20+$C$21) | AF62: =IF(AF52="","",AF52*$C$20+$C$21) | AG62: =IF(AG52="","",AG52*$C$20+$C$21) | AH62: =IF(AH52="","",AH52*$C$20+$C$21) | AI62: =IF(AI52="","",AI52*$C$20+$C$21) | ... AM62: =IF(AM52="","",AM52*$C$20+$C$21) | AO62: =IF(AO52="","",AO52*$AP$20+$AP$21) | AP62: =IF(AP52="","",AP52*$AP$20+$AP$21) | AQ62: =IF(AQ52="","",AQ52*$AP$20+$AP$21) | AR62: =IF(AR52="","",AR52*$AP$20+$AP$21) | AS62: =IF(AS52="","",AS52*$AP$20+$AP$21) | AT62: =IF(AT52="","",AT52*$AP$20+$AP$21) | AU62: =IF(AU52="","",AU52*$AP$20+$AP$21) | AV62: =IF(AV52="","",AV52*$AP$20+$AP$21) | ... AZ62: =IF(AZ52="","",AZ52*$AP$20+$AP$21)

Sheet Results
D1: Target protein (g/L) | Q1: Impurity 1: | R1: =IF(B10="","",B10) | T1: Units: | U1: =IF(B11="","",B11) | AD1: Impurity 2: | AE1: =IF(B14="","",B14) | AG1: Units: | AH1: =IF(B15="","",B15)
A2: Uniform value (optional): | D2: C0 | Q2: C0 | AD2: C0
A3: Resin vol (µL): | B3: =IF(Inputs!B12="","",Inputs!B12) | D3: =IF($B$8="",IF('UV calibration and raw data'!O55="",IF(Inputs!Q33="","",Inputs!Q33),'UV calibration and raw data'!O55),Results!$B$8) | E3: =IF($B$8="",IF('UV calibration and raw data'!P55="",IF(Inputs!R33="","",Inputs!R33),'UV calibration and raw data'!P55),Results!$B$8) | F3: =IF($B$8="",IF('UV calibration and raw data'!Q55="",IF(Inputs!S33="","",Inputs!S33),'UV calibration and raw data'!Q55),Results!$B$8) | G3: =IF($B$8="",IF('UV calibration and raw data'!R55="",IF(Inputs!T33="","",Inputs!T33),'UV calibration and raw data'!R55),Results!$B$8) | H3: =IF($B$8="",IF('UV calibration and raw data'!S55="",IF(Inputs!U33="","",Inputs!U33),'UV calibration and raw data'!S55),Results!$B$8) | I3: =IF($B$8="",IF('UV calibration and raw data'!T55="",IF(Inputs!V33="","",Inputs!V33),'UV calibration and raw data'!T55),Results!$B$8) | J3: =IF($B$8="",IF('UV calibration and raw data'!U55="",IF(Inputs!W33="","",Inputs!W33),'UV calibration and raw data'!U55),Results!$B$8) | K3: =IF($B$8="",IF('UV calibration and raw data'!V55="",IF(Inputs!X33="","",Inputs!X33),'UV calibration and raw data'!V55),Results!$B$8) | ... O3: =IF($B$8="",IF('UV calibration and raw data'!Z55="",IF(Inputs!AB33="","",Inputs!AB33),'UV calibration and raw data'!Z55),Results!$B$8) | Q3: =IF($B$12="","",$B$12) | R3: =IF($B$12="","",$B$12) | S3: =IF($B$12="","",$B$12) | T3: =IF($B$12="","",$B$12) | U3: =IF($B$12="","",$B$12) | V3: =IF($B$12="","",$B$12) | W3: =IF($B$12="","",$B$12) | X3: =IF($B$12="","",$B$12) | ... AB3: =IF($B$12="","",$B$12) | AD3: =IF($B$16="","",$B$16) | AE3: =IF($B$16="","",$B$16) | AF3: =IF($B$16="","",$B$16) | AG3: =IF($B$16="","",$B$16) | AH3: =IF($B$16="","",$B$16) | AI3: =IF($B$16="","",$B$16) | AJ3: =IF($B$16="","",$B$16) | AK3: =IF($B$16="","",$B$16) | ... AO3: =IF($B$16="","",$B$16)
B4: =IF(Inputs!B13="","",Inputs!B13) | D4: =IF($B$8="",IF('UV calibration and raw data'!O56="",IF(Inputs!Q34="","",Inputs!Q34),'UV calibration and raw data'!O56),Results!$B$8) | E4: =IF($B$8="",IF('UV calibration and raw data'!P56="",IF(Inputs!R34="","",Inputs!R34),'UV calibration and raw data'!P56),Results!$B$8) | F4: =IF($B$8="",IF('UV calibration and raw data'!Q56="",IF(Inputs!S34="","",Inputs!S34),'UV calibration and raw data'!Q56),Results!$B$8) | G4: =IF($B$8="",IF('UV calibration and raw data'!R56="",IF(Inputs!T34="","",Inputs!T34),'UV calibration and raw data'!R56),Results!$B$8) | H4: =IF($B$8="",IF('UV calibration and raw data'!S56="",IF(Inputs!U34="","",Inputs!U34),'UV calibration and raw data'!S56),Results!$B$8) | I4: =IF($B$8="",IF('UV calibration and raw data'!T56="",IF(Inputs!V34="","",Inputs!V34),'UV calibration and raw data'!T56),Results!$B$8) | J4: =IF($B$8="",IF('UV calibration and raw data'!U56="",IF(Inputs!W34="","",Inputs!W34),'UV calibration and raw data'!U56),Results!$B$8) | K4: =IF($B$8="",IF('UV calibration and raw data'!V56="",IF(Inputs!X34="","",Inputs!X34),'UV calibration and raw data'!V56),Results!$B$8) | ... O4: =IF($B$8="",IF('UV calibration and raw data'!Z56="",IF(Inputs!AB34="","",Inputs!AB34),'UV calibration and raw data'!Z56),Results!$B$8) | Q4: =IF($B$12="","",$B$12) | R4: =IF($B$12="","",$B$12) | S4: =IF($B$12="","",$B$12) | T4: =IF($B$12="","",$B$12) | U4: =IF($B$12="","",$B$12) | V4: =IF($B$12="","",$B$12) | W4: =IF($B$12="","",$B$12) | X4: =IF($B$12="","",$B$12) | ... AB4: =IF($B$12="","",$B$12) | AD4: =IF($B$16="","",$B$16) | AE4: =IF($B$16="","",$B$16) | AF4: =IF($B$16="","",$B$16) | AG4: =IF($B$16="","",$B$16) | AH4: =IF($B$16="","",$B$16) | AI4: =IF($B$16="","",$B$16) | AJ4: =IF($B$16="","",$B$16) | AK4: =IF($B$16="","",$B$16) | ... AO4: =IF($B$16="","",$B$16)
A5: Load vol (µL): | B5: =IF(Inputs!B14="","",Inputs!B14) | D5: =IF($B$8="",IF('UV calibration and raw data'!O57="",IF(Inputs!Q35="","",Inputs!Q35),'UV calibration and raw data'!O57),Results!$B$8) | E5: =IF($B$8="",IF('UV calibration and raw data'!P57="",IF(Inputs!R35="","",Inputs!R35),'UV calibration and raw data'!P57),Results!$B$8) | F5: =IF($B$8="",IF('UV calibration and raw data'!Q57="",IF(Inputs!S35="","",Inputs!S35),'UV calibration and raw data'!Q57),Results!$B$8) | G5: =IF($B$8="",IF('UV calibration and raw data'!R57="",IF(Inputs!T35="","",Inputs!T35),'UV calibration and raw data'!R57),Results!$B$8) | H5: =IF($B$8="",IF('UV calibration and raw data'!S57="",IF(Inputs!U35="","",Inputs!U35),'UV calibration and raw data'!S57),Results!$B$8) | I5: =IF($B$8="",IF('UV calibration and raw data'!T57="",IF(Inputs!V35="","",Inputs!V35),'UV calibration and raw data'!T57),Results!$B$8) | J5: =IF($B$8="",IF('UV calibration and raw data'!U57="",IF(Inputs!W35="","",Inputs!W35),'UV calibration and raw data'!U57),Results!$B$8) | K5: =IF($B$8="",IF('UV calibration and raw data'!V57="",IF(Inputs!X35="","",Inputs!X35),'UV calibration and raw data'!V57),Results!$B$8) | ... O5: =IF($B$8="",IF('UV calibration and raw data'!Z57="",IF(Inputs!AB35="","",Inputs!AB35),'UV calibration and raw data'!Z57),Results!$B$8) | Q5: =IF($B$12="","",$B$12) | R5: =IF($B$12="","",$B$12) | S5: =IF($B$12="","",$B$12) | T5: =IF($B$12="","",$B$12) | U5: =IF($B$12="","",$B$12) | V5: =IF($B$12="","",$B$12) | W5: =IF($B$12="","",$B$12) | X5: =IF($B$12="","",$B$12) | ... AB5: =IF($B$12="","",$B$12) | AD5: =IF($B$16="","",$B$16) | AE5: =IF($B$16="","",$B$16) | AF5: =IF($B$16="","",$B$16) | AG5: =IF($B$16="","",$B$16) | AH5: =IF($B$16="","",$B$16) | AI5: =IF($B$16="","",$B$16) | AJ5: =IF($B$16="","",$B$16) | AK5: =IF($B$16="","",$B$16) | ... AO5: =IF($B$16="","",$B$16)
D6: =IF($B$8="",IF('UV calibration and raw data'!O58="",IF(Inputs!Q36="","",Inputs!Q36),'UV calibration and raw data'!O58),Results!$B$8) | E6: =IF($B$8="",IF('UV calibration and raw data'!P58="",IF(Inputs!R36="","",Inputs!R36),'UV calibration and raw data'!P58),Results!$B$8) | F6: =IF($B$8="",IF('UV calibration and raw data'!Q58="",IF(Inputs!S36="","",Inputs!S36),'UV calibration and raw data'!Q58),Results!$B$8) | G6: =IF($B$8="",IF('UV calibration and raw data'!R58="",IF(Inputs!T36="","",Inputs!T36),'UV calibration and raw data'!R58),Results!$B$8) | H6: =IF($B$8="",IF('UV calibration and raw data'!S58="",IF(Inputs!U36="","",Inputs!U36),'UV calibration and raw data'!S58),Results!$B$8) | I6: =IF($B$8="",IF('UV calibration and raw data'!T58="",IF(Inputs!V36="","",Inputs!V36),'UV calibration and raw data'!T58),Results!$B$8) | J6: =IF($B$8="",IF('UV calibration and raw data'!U58="",IF(Inputs!W36="","",Inputs!W36),'UV calibration and raw data'!U58),Results!$B$8) | K6: =IF($B$8="",IF('UV calibration and raw data'!V58="",IF(Inputs!X36="","",Inputs!X36),'UV calibration and raw data'!V58),Results!$B$8) | ... O6: =IF($B$8="",IF('UV calibration and raw data'!Z58="",IF(Inputs!AB36="","",Inputs!AB36),'UV calibration and raw data'!Z58),Results!$B$8) | Q6: =IF($B$12="","",$B$12) | R6: =IF($B$12="","",$B$12) | S6: =IF($B$12="","",$B$12) | T6: =IF($B$12="","",$B$12) | U6: =IF($B$12="","",$B$12) | V6: =IF($B$12="","",$B$12) | W6: =IF($B$12="","",$B$12) | X6: =IF($B$12="","",$B$12) | ... AB6: =IF($B$12="","",$B$12) | AD6: =IF($B$16="","",$B$16) | AE6: =IF($B$16="","",$B$16) | AF6: =IF($B$16="","",$B$16) | AG6: =IF($B$16="","",$B$16) | AH6: =IF($B$16="","",$B$16) | AI6: =IF($B$16="","",$B$16) | AJ6: =IF($B$16="","",$B$16) | AK6: =IF($B$16="","",$B$16) | ... AO6: =IF($B$16="","",$B$16)
A7: Load concentrations: | D7: =IF($B$8="",IF('UV calibration and raw data'!O59="",IF(Inputs!Q37="","",Inputs!Q37),'UV calibration and raw data'!O59),Results!$B$8) | E7: =IF($B$8="",IF('UV calibration and raw data'!P59="",IF(Inputs!R37="","",Inputs!R37),'UV calibration and raw data'!P59),Results!$B$8) | F7: =IF($B$8="",IF('UV calibration and raw data'!Q59="",IF(Inputs!S37="","",Inputs!S37),'UV calibration and raw data'!Q59),Results!$B$8) | G7: =IF($B$8="",IF('UV calibration and raw data'!R59="",IF(Inputs!T37="","",Inputs!T37),'UV calibration and raw data'!R59),Results!$B$8) | H7: =IF($B$8="",IF('UV calibration and raw data'!S59="",IF(Inputs!U37="","",Inputs!U37),'UV calibration and raw data'!S59),Results!$B$8) | I7: =IF($B$8="",IF('UV calibration and raw data'!T59="",IF(Inputs!V37="","",Inputs!V37),'UV calibration and raw data'!T59),Results!$B$8) | J7: =IF($B$8="",IF('UV calibration and raw data'!U59="",IF(Inputs!W37="","",Inputs!W37),'UV calibration and raw data'!U59),Results!$B$8) | K7: =IF($B$8="",IF('UV calibration and raw data'!V59="",IF(Inputs!X37="","",Inputs!X37),'UV calibration and raw data'!V59),Results!$B$8) | ... O7: =IF($B$8="",IF('UV calibration and raw data'!Z59="",IF(Inputs!AB37="","",Inputs!AB37),'UV calibration and raw data'!Z59),Results!$B$8) | Q7: =IF($B$12="","",$B$12) | R7: =IF($B$12="","",$B$12) | S7: =IF($B$12="","",$B$12) | T7: =IF($B$12="","",$B$12) | U7: =IF($B$12="","",$B$12) | V7: =IF($B$12="","",$B$12) | W7: =IF($B$12="","",$B$12) | X7: =IF($B$12="","",$B$12) | ... AB7: =IF($B$12="","",$B$12) | AD7: =IF($B$16="","",$B$16) | AE7: =IF($B$16="","",$B$16) | AF7: =IF($B$16="","",$B$16) | AG7: =IF($B$16="","",$B$16) | AH7: =IF($B$16="","",$B$16) | AI7: =IF($B$16="","",$B$16) | AJ7: =IF($B$16="","",$B$16) | AK7: =IF($B$16="","",$B$16) | ... AO7: =IF($B$16="","",$B$16)
A8: Target protein (g/L): | B8: =IF(Inputs!B15="","",Inputs!B15) | D8: =IF($B$8="",IF('UV calibration and raw data'!O60="",IF(Inputs!Q38="","",Inputs!Q38),'UV calibration and raw data'!O60),Results!$B$8) | E8: =IF($B$8="",IF('UV calibration and raw data'!P60="",IF(Inputs!R38="","",Inputs!R38),'UV calibration and raw data'!P60),Results!$B$8) | F8: =IF($B$8="",IF('UV calibration and raw data'!Q60="",IF(Inputs!S38="","",Inputs!S38),'UV calibration and raw data'!Q60),Results!$B$8) | G8: =IF($B$8="",IF('UV calibration and raw data'!R60="",IF(Inputs!T38="","",Inputs!T38),'UV calibration and raw data'!R60),Results!$B$8) | H8: =IF($B$8="",IF('UV calibration and raw data'!S60="",IF(Inputs!U38="","",Inputs!U38),'UV calibration and raw data'!S60),Results!$B$8) | I8: =IF($B$8="",IF('UV calibration and raw data'!T60="",IF(Inputs!V38="","",Inputs!V38),'UV calibration and raw data'!T60),Results!$B$8) | J8: =IF($B$8="",IF('UV calibration and raw data'!U60="",IF(Inputs!W38="","",Inputs!W38),'UV calibration and raw data'!U60),Results!$B$8) | K8: =IF($B$8="",IF('UV calibration and raw data'!V60="",IF(Inputs!X38="","",Inputs!X38),'UV calibration and raw data'!V60),Results!$B$8) | ... O8: =IF($B$8="",IF('UV calibration and raw data'!Z60="",IF(Inputs!AB38="","",Inputs!AB38),'UV calibration and raw data'!Z60),Results!$B$8) | Q8: =IF($B$12="","",$B$12) | R8: =IF($B$12="","",$B$12) | S8: =IF($B$12="","",$B$12) | T8: =IF($B$12="","",$B$12) | U8: =IF($B$12="","",$B$12) | V8: =IF($B$12="","",$B$12) | W8: =IF($B$12="","",$B$12) | X8: =IF($B$12="","",$B$12) | ... AB8: =IF($B$12="","",$B$12) | AD8: =IF($B$16="","",$B$16) | AE8: =IF($B$16="","",$B$16) | AF8: =IF($B$16="","",$B$16) | AG8: =IF($B$16="","",$B$16) | AH8: =IF($B$16="","",$B$16) | AI8: =IF($B$16="","",$B$16) | AJ8: =IF($B$16="","",$B$16) | AK8: =IF($B$16="","",$B$16) | ... AO8: =IF($B$16="","",$B$16)
D9: =IF($B$8="",IF('UV calibration and raw data'!O61="",IF(Inputs!Q39="","",Inputs!Q39),'UV calibration and raw data'!O61),Results!$B$8) | E9: =IF($B$8="",IF('UV calibration and raw data'!P61="",IF(Inputs!R39="","",Inputs!R39),'UV calibration and raw data'!P61),Results!$B$8) | F9: =IF($B$8="",IF('UV calibration and raw data'!Q61="",IF(Inputs!S39="","",Inputs!S39),'UV calibration and raw data'!Q61),Results!$B$8) | G9: =IF($B$8="",IF('UV calibration and raw data'!R61="",IF(Inputs!T39="","",Inputs!T39),'UV calibration and raw data'!R61),Results!$B$8) | H9: =IF($B$8="",IF('UV calibration and raw data'!S61="",IF(Inputs!U39="","",Inputs!U39),'UV calibration and raw data'!S61),Results!$B$8) | I9: =IF($B$8="",IF('UV calibration and raw data'!T61="",IF(Inputs!V39="","",Inputs!V39),'UV calibration and raw data'!T61),Results!$B$8) | J9: =IF($B$8="",IF('UV calibration and raw data'!U61="",IF(Inputs!W39="","",Inputs!W39),'UV calibration and raw data'!U61),Results!$B$8) | K9: =IF($B$8="",IF('UV calibration and raw data'!V61="",IF(Inputs!X39="","",Inputs!X39),'UV calibration and raw data'!V61),Results!$B$8) | ... O9: =IF($B$8="",IF('UV calibration and raw data'!Z61="",IF(Inputs!AB39="","",Inputs!AB39),'UV calibration and raw data'!Z61),Results!$B$8) | Q9: =IF($B$12="","",$B$12) | R9: =IF($B$12="","",$B$12) | S9: =IF($B$12="","",$B$12) | T9: =IF($B$12="","",$B$12) | U9: =IF($B$12="","",$B$12) | V9: =IF($B$12="","",$B$12) | W9: =IF($B$12="","",$B$12) | X9: =IF($B$12="","",$B$12) | ... AB9: =IF($B$12="","",$B$12) | AD9: =IF($B$16="","",$B$16) | AE9: =IF($B$16="","",$B$16) | AF9: =IF($B$16="","",$B$16) | AG9: =IF($B$16="","",$B$16) | AH9: =IF($B$16="","",$B$16) | AI9: =IF($B$16="","",$B$16) | AJ9: =IF($B$16="","",$B$16) | AK9: =IF($B$16="","",$B$16) | ... AO9: =IF($B$16="","",$B$16)
A10: Impurity 1 name: | D10: =IF($B$8="",IF('UV calibration and raw data'!O62="",IF(Inputs!Q40="","",Inputs!Q40),'UV calibration and raw data'!O62),Results!$B$8) | E10: =IF($B$8="",IF('UV calibration and raw data'!P62="",IF(Inputs!R40="","",Inputs!R40),'UV calibration and raw data'!P62),Results!$B$8) | F10: =IF($B$8="",IF('UV calibration and raw data'!Q62="",IF(Inputs!S40="","",Inputs!S40),'UV calibration and raw data'!Q62),Results!$B$8) | G10: =IF($B$8="",IF('UV calibration and raw data'!R62="",IF(Inputs!T40="","",Inputs!T40),'UV calibration and raw data'!R62),Results!$B$8) | H10: =IF($B$8="",IF('UV calibration and raw data'!S62="",IF(Inputs!U40="","",Inputs!U40),'UV calibration and raw data'!S62),Results!$B$8) | I10: =IF($B$8="",IF('UV calibration and raw data'!T62="",IF(Inputs!V40="","",Inputs!V40),'UV calibration and raw data'!T62),Results!$B$8) | J10: =IF($B$8="",IF('UV calibration and raw data'!U62="",IF(Inputs!W40="","",Inputs!W40),'UV calibration and raw data'!U62),Results!$B$8) | K10: =IF($B$8="",IF('UV calibration and raw data'!V62="",IF(Inputs!X40="","",Inputs!X40),'UV calibration and raw data'!V62),Results!$B$8) | ... O10: =IF($B$8="",IF('UV calibration and raw data'!Z62="",IF(Inputs!AB40="","",Inputs!AB40),'UV calibration and raw data'!Z62),Results!$B$8) | Q10: =IF($B$12="","",$B$12) | R10: =IF($B$12="","",$B$12) | S10: =IF($B$12="","",$B$12) | T10: =IF($B$12="","",$B$12) | U10: =IF($B$12="","",$B$12) | V10: =IF($B$12="","",$B$12) | W10: =IF($B$12="","",$B$12) | X10: =IF($B$12="","",$B$12) | ... AB10: =IF($B$12="","",$B$12) | AD10: =IF($B$16="","",$B$16) | AE10: =IF($B$16="","",$B$16) | AF10: =IF($B$16="","",$B$16) | AG10: =IF($B$16="","",$B$16) | AH10: =IF($B$16="","",$B$16) | AI10: =IF($B$16="","",$B$16) | AJ10: =IF($B$16="","",$B$16) | AK10: =IF($B$16="","",$B$16) | ... AO10: =IF($B$16="","",$B$16)
A11: Impurity 1 units:
A12: Impurity 1 conc, C0: | D12: C | F12: Value <>0 | Q12: C | S12: Value <>0 | AD12: C | AF12: Value <>0
D13: =IF('UV calibration and raw data'!B55="","",'UV calibration and raw data'!B55) | E13: =IF('UV calibration and raw data'!C55="","",'UV calibration and raw data'!C55) | F13: =IF('UV calibration and raw data'!D55="","",'UV calibration and raw data'!D55) | G13: =IF('UV calibration and raw data'!E55="","",'UV calibration and raw data'!E55) | H13: =IF('UV calibration and raw data'!F55="","",'UV calibration and raw data'!F55) | I13: =IF('UV calibration and raw data'!G55="","",'UV calibration and raw data'!G55) | J13: =IF('UV calibration and raw data'!H55="","",'UV calibration and raw data'!H55) | K13: =IF('UV calibration and raw data'!I55="","",'UV calibration and raw data'!I55) | ... O13: =IF('UV calibration and raw data'!M55="","",'UV calibration and raw data'!M55)
